<?xml version='1.0'?>
<sdf version='1.6'>
  <model name='hummingbot'>
    <link name='main_box'>
      <pose>0.0 0.0 0.07 0 -0 0</pose>
      <inertial>
        <mass>50</mass>
        <inertia>
          <ixx>0.00533333</ixx>
          <ixy>0</ixy>
          <ixz>0</ixz>
          <iyy>0.00970833</iyy>
          <iyz>0</iyz>
          <izz>0.00970833</izz>
        </inertia>
        <pose>0 0 0 0 -0 0</pose>
      </inertial>
      <gravity>1</gravity>
      <self_collide>0</self_collide>
      <kinematic>0</kinematic>
      <enable_wind>0</enable_wind>
      <visual name='visual'>
        <pose frame=''>0 0 0 0 -0 0</pose>
        <geometry>
          <box>
            <size>0.13 0.08 0.08</size>
          </box>
        </geometry>
        <material>
          <lighting>1</lighting>
          <script>a
            <uri>file://media/materials/scripts/gazebo.material</uri>
            <name>Gazebo/Grey</name>
          </script>
          <shader type='vertex'>
            <normal_map>__default__</normal_map>
          </shader>
          <ambient>0.3 0.3 0.3 1</ambient>
          <diffuse>0.7 0.7 0.7 1</diffuse>
          <specular>0.01 0.01 0.01 1</specular>
          <emissive>0 0 0 1</emissive>
        </material>
        <transparency>0</transparency>
        <cast_shadows>1</cast_shadows>
      </visual>
      <collision name='collision'>
        <laser_retro>0</laser_retro>
        <max_contacts>10</max_contacts>
        <pose frame=''>0 0 0 0 -0 0</pose>
        <geometry>
          <box>
            <size>>0.13 0.08 0.08</size>
          </box>
        </geometry>
      </collision>
    </link>
    <link name='ball_wheel'>
      <pose frame=''>-0.048 -0.002958 0.0127 0 -0 0</pose>
      <inertial>
        <mass>0.01</mass>
        <inertia>
          <ixx>0.00000645</ixx>
          <ixy>0</ixy>
          <ixz>0</ixz>
          <iyy>0.00000645</iyy>
          <iyz>0</iyz>
          <izz>0.00000645</izz>
        </inertia>
        <pose frame=''>0 0 0 0 -0 0</pose>
      </inertial>
      <gravity>1</gravity>
      <self_collide>0</self_collide>
      <kinematic>0</kinematic>
      <enable_wind>0</enable_wind>
      <visual name='visual'>
        <pose frame=''>0 0 0 0 -0 0</pose>
        <geometry>
          <sphere>
            <radius>0.015</radius>
          </sphere>
        </geometry>
        <material>
          <lighting>1</lighting>
          <script>
            <uri>file://media/materials/scripts/gazebo.material</uri>
            <name>Gazebo/Grey</name>
          </script>
          <shader type='vertex'>
            <normal_map>__default__</normal_map>
          </shader>
          <ambient>0.3 0.3 0.3 1</ambient>
          <diffuse>0.7 0.7 0.7 1</diffuse>
          <specular>0.01 0.01 0.01 1</specular>
          <emissive>0 0 0 1</emissive>
        </material>
        <transparency>0</transparency>
        <cast_shadows>1</cast_shadows>
      </visual>
      <collision name='collision'>
        <laser_retro>0</laser_retro>
        <max_contacts>10</max_contacts>
        <pose frame=''>0 0 0 0 -0 0</pose>
        <geometry>
          <sphere>
            <radius>0.015</radius>
          </sphere>
        </geometry>
      </collision>
    </link>
    <link name='camera_link'>
      <pose frame=''>0.065 0 0.115 0 0.2  0</pose>
      <inertial>
        <mass>0.03</mass>
        <inertia>
          <ixx>0</ixx>
          <iyy>0</iyy>
          <izz>0</izz>
          <ixy>0</ixy>
          <ixz>0</ixz>
          <iyz>0</iyz>
        </inertia>
        <pose frame='main_box'>0 0 0 0 0 0</pose>
      </inertial>
      <sensor name='camera' type='camera'>
        <camera name='__default__'>
          <horizontal_fov>2.79253</horizontal_fov>
          <image>
            <width>1280</width>
            <height>720</height>
          </image>
          <clip>
            <near>0.01</near>
            <far>1</far>
          </clip>
        </camera>
        <always_on>1</always_on>
        <update_rate>10</update_rate>
        <visualize>1</visualize>
      </sensor>
      <self_collide>0</self_collide>
      <enable_wind>0</enable_wind>
      <kinematic>0</kinematic>
      <gravity>1</gravity>
      <visual name='visual'>
        <geometry>
          <box>
            <size>0.024 0.025 0.01</size>
          </box>
        </geometry>
        <material>
          <shader type='pixel'>
            <normal_map>__default__</normal_map>
          </shader>
          <script>
            <name>ModelPreview_7::camera_link::visual_MATERIAL_</name>
            <uri>__default__</uri>
          </script>
          <ambient>0 0 0 1</ambient>
          <diffuse>0 0 0 1</diffuse>
          <specular>0 0 0 1</specular>
          <emissive>0 0 0 1</emissive>
        </material>
        <pose frame=''>0 0 0 0 -0 0</pose>
        <transparency>0</transparency>
        <cast_shadows>1</cast_shadows>
      </visual>
      <collision name='collision'>
        <laser_retro>0</laser_retro>
        <max_contacts>10</max_contacts>
        <pose frame=''>0 0 0 0 -0 0</pose>
        <geometry>
          <box>
            <size>0.024 0.021 0.01</size>
          </box>
        </geometry>
      </collision>
    </link>
    <link name='left_wheel'>
      <pose frame=''>0.065 0.049 0.03 1.5707 -0 0</pose>
      <inertial>
        <mass>0.2</mass>
        <inertia>
          <ixx>0.145833</ixx>
          <ixy>0</ixy>
          <ixz>0</ixz>
          <iyy>0.145833</iyy>
          <iyz>0</iyz>
          <izz>0.125</izz>
        </inertia>
        <pose frame=''>0 0 0 0 -0 0</pose>
      </inertial>
      <gravity>1</gravity>
      <self_collide>0</self_collide>
      <kinematic>0</kinematic>
      <enable_wind>0</enable_wind>
      <visual name='visual'>
        <pose frame=''>0 0 0 0 -0 0</pose>
        <geometry>
          <cylinder>
            <radius>0.03</radius>
            <length>0.015</length>
          </cylinder>
        </geometry>
        <material>
          <lighting>1</lighting>
          <script>
            <uri>file://media/materials/scripts/gazebo.material</uri>
            <name>Gazebo/Grey</name>
          </script>
          <shader type='vertex'>
            <normal_map>__default__</normal_map>
          </shader>
          <ambient>0.3 0.3 0.3 1</ambient>
          <diffuse>0.7 0.7 0.7 1</diffuse>
          <specular>0.01 0.01 0.01 1</specular>
          <emissive>0 0 0 1</emissive>
        </material>
        <transparency>0</transparency>
        <cast_shadows>1</cast_shadows>
      </visual>
      <collision name='collision'>
        <laser_retro>0</laser_retro>
        <max_contacts>10</max_contacts>
        <pose frame=''>0 0 0 0 -0 0</pose>
        <geometry>
          <cylinder>
            <radius>0.03</radius>
            <length>0.015</length>
          </cylinder>
        </geometry>
       </collision>
    </link>
    <link name='right_wheel'>
      <pose frame=''>0.065 -0.049 0.03 1.5707 -0 0</pose>
      <inertial>
        <mass>0.1</mass>
        <inertia>
          <ixx>0.145833</ixx>
          <ixy>0</ixy>
          <ixz>0</ixz>
          <iyy>0.145833</iyy>
          <iyz>0</iyz>
          <izz>0.125</izz>
        </inertia>
        <pose frame=''>0 0 0 0 -0 0</pose>
      </inertial>
      <gravity>1</gravity>
      <self_collide>0</self_collide>
      <kinematic>0</kinematic>
      <enable_wind>0</enable_wind>
      <visual name='visual'>
        <pose frame=''>0 0 0 0 -0 0</pose>
        <geometry>
          <cylinder>
            <radius>0.03</radius>
            <length>0.015</length>
          </cylinder>
        </geometry>
        <material>
          <lighting>1</lighting>
          <script>
            <uri>file://media/materials/scripts/gazebo.material</uri>
            <name>Gazebo/Grey</name>
          </script>
          <shader type='vertex'>
            <normal_map>__default__</normal_map>
          </shader>
          <ambient>0.3 0.3 0.3 1</ambient>
          <diffuse>0.7 0.7 0.7 1</diffuse>
          <specular>0.01 0.01 0.01 1</specular>
          <emissive>0 0 0 1</emissive>
        </material>
        <transparency>0</transparency>
        <cast_shadows>1</cast_shadows>
      </visual>
      <collision name='collision'>
        <laser_retro>0</laser_retro>
        <max_contacts>10</max_contacts>
        <pose frame=''>0 0 0 0 -0 0</pose>
        <geometry>
          <cylinder>
            <radius>0.03</radius>
            <length>0.015</length>
          </cylinder>
        </geometry>
      </collision>
    </link>
    <joint name='ball_link' type='ball'>
      <parent>main_box</parent>
      <child>ball_wheel</child>
      <pose frame=''>0 0 0 0 -0 0</pose>
      <physics>
        <ode>
          <limit>
            <cfm>0</cfm>
            <erp>0.2</erp>
          </limit>
          <suspension>
            <cfm>0</cfm>
            <erp>0.2</erp>
          </suspension>
        </ode>
      </physics>
    </joint>
    <joint name='camera_joint' type='fixed'>
      <parent>main_box</parent>
      <child>camera_link</child>
      <pose frame=''>0 0 0 0 -0 0</pose>
      <physics>
        <ode>
          <limit>
            <cfm>0</cfm>
            <erp>0.2</erp>
          </limit>
          <suspension>
            <cfm>0</cfm>
            <erp>0.2</erp>
          </suspension>
        </ode>
      </physics>
    </joint>
    <joint name='left_wheel_hinge' type='revolute'>
      <parent>main_box</parent>
      <child>left_wheel</child>
      <pose frame=''>0 0 0 0 -0 0</pose>
      <axis>
        <xyz>0 0 1</xyz>
        <use_parent_model_frame>0</use_parent_model_frame>
        <limit>
          <lower>-1.79769e+308</lower>
          <upper>1.79769e+308</upper>
          <effort>-1</effort>
          <velocity>-1</velocity>
        </limit>
        <dynamics>
          <spring_reference>0</spring_reference>
          <spring_stiffness>0</spring_stiffness>
          <damping>0</damping>
          <friction>0</friction>
        </dynamics>
      </axis>
      <physics>
        <ode>
          <limit>
            <cfm>0</cfm>
            <erp>0.2</erp>
          </limit>
          <suspension>
            <cfm>0</cfm>
            <erp>0.2</erp>
          </suspension>
        </ode>
      </physics>
    </joint>
    <joint name='right_wheel_hinge' type='revolute'>
      <parent>main_box</parent>
      <child>right_wheel</child>
      <pose frame=''>0 0 0 0 -0 0</pose>
      <axis>
        <xyz>0 0 1</xyz>
        <use_parent_model_frame>0</use_parent_model_frame>
        <limit>
          <lower>-1.79769e+308</lower>
          <upper>1.79769e+308</upper>
          <effort>-1</effort>
          <velocity>-1</velocity>
        </limit>
        <dynamics>
          <spring_reference>0</spring_reference>
          <spring_stiffness>0</spring_stiffness>
          <damping>0</damping>
          <friction>0</friction>
        </dynamics>
      </axis>
      <physics>
        <ode>
          <limit>
            <cfm>0</cfm>
            <erp>0.2</erp>
          </limit>
          <suspension>
            <cfm>0</cfm>
            <erp>0.2</erp>
          </suspension>
        </ode>
      </physics>
    </joint>
    <static>0</static>
    <allow_auto_disable>1</allow_auto_disable>
   </model>
 </sdf>
